Workbook

Sheet Daily Planner
A1: Daily Planner
A2: Fill in Subject / Topic / Subtopic / Hours each day. Day, Date and Streak are formula-driven — do not overtype them.
A3: Day | B3: Date | C3: Today's Goal | D3: Subject | E3: Topic | F3: Subtopic | G3: Estimated Hours | H3: Completed | I3: Revision Due | J3: Notes | K3: Streak (auto)
A4: =IF(B4="","",TEXT(B4,"dddd")) -> Wednesday | B4: 46239 | D4: Python Advanced | E4: CPython Internals | F4: PyObject struct & object layout | G4: 1 | H4: TRUE | I4: =FALSE() -> FALSE | K4: =IF(H4=TRUE(),1,0) -> 1
A5: =IF(B5="","",TEXT(B5,"dddd")) -> Thursday | B5: 46240 | H5: =FALSE() -> FALSE | I5: =FALSE() -> FALSE | K5: =IF(H5=TRUE(),K4+1,0) -> 0
A6: =IF(B6="","",TEXT(B6,"dddd")) -> Friday | B6: 46241 | H6: =FALSE() -> FALSE | I6: =FALSE() -> FALSE | K6: =IF(H6=TRUE(),K5+1,0) -> 0
A7: =IF(B7="","",TEXT(B7,"dddd")) -> Saturday | B7: 46242 | H7: =FALSE() -> FALSE | I7: =FALSE() -> FALSE | K7: =IF(H7=TRUE(),K6+1,0) -> 0
A8: =IF(B8="","",TEXT(B8,"dddd")) -> Sunday | B8: 46243 | H8: =FALSE() -> FALSE | I8: =FALSE() -> FALSE | K8: =IF(H8=TRUE(),K7+1,0) -> 0
A9: =IF(B9="","",TEXT(B9,"dddd")) -> Monday | B9: 46244 | H9: =FALSE() -> FALSE | I9: =FALSE() -> FALSE | K9: =IF(H9=TRUE(),K8+1,0) -> 0
A10: =IF(B10="","",TEXT(B10,"dddd")) -> Tuesday | B10: 46245 | H10: =FALSE() -> FALSE | I10: =FALSE() -> FALSE | K10: =IF(H10=TRUE(),K9+1,0) -> 0
A11: =IF(B11="","",TEXT(B11,"dddd")) -> Wednesday | B11: 46246 | H11: =FALSE() -> FALSE | I11: =FALSE() -> FALSE | K11: =IF(H11=TRUE(),K10+1,0) -> 0
A12: =IF(B12="","",TEXT(B12,"dddd")) -> Thursday | B12: 46247 | H12: =FALSE() -> FALSE | I12: =FALSE() -> FALSE | K12: =IF(H12=TRUE(),K11+1,0) -> 0
A13: =IF(B13="","",TEXT(B13,"dddd")) -> Friday | B13: 46248 | H13: =FALSE() -> FALSE | I13: =FALSE() -> FALSE | K13: =IF(H13=TRUE(),K12+1,0) -> 0
A14: =IF(B14="","",TEXT(B14,"dddd")) -> Saturday | B14: 46249 | H14: =FALSE() -> FALSE | I14: =FALSE() -> FALSE | K14: =IF(H14=TRUE(),K13+1,0) -> 0
A15: =IF(B15="","",TEXT(B15,"dddd")) -> Sunday | B15: 46250 | H15: =FALSE() -> FALSE | I15: =FALSE() -> FALSE | K15: =IF(H15=TRUE(),K14+1,0) -> 0
A16: =IF(B16="","",TEXT(B16,"dddd")) -> Monday | B16: 46251 | H16: =FALSE() -> FALSE | I16: =FALSE() -> FALSE | K16: =IF(H16=TRUE(),K15+1,0) -> 0
... A123: =IF(B123="","",TEXT(B123,"dddd")) -> Wednesday | B123: 46358 | H123: =FALSE() -> FALSE | I123: =FALSE() -> FALSE | K123: =IF(H123=TRUE(),K122+1,0) -> 0

Sheet Weekly Review
A1: Weekly Review
A2: Hours Studied pulls automatically from Daily Planner. Fill in the reflection columns every Sunday.
A3: Week # | B3: Week Starting | C3: Week Ending | D3: Hours Studied (auto) | E3: Concepts Learned | F3: Problems Solved | G3: Research Papers | H3: Projects | I3: Weak Areas | J3: Action Items
A4: 1 | B4: 46239 | C4: =B4+6 -> 46245 | D4: =SUMIFS('Daily Planner'!$G$4:$G$123,'Daily Planner'!$B$4:$B$123,">="&B4,'Daily Planner'!$B$4:$B$123,"<="&C4,'Daily Planner'!$H$4:$H$123,TRUE()) -> 1
A5: 2 | B5: 46246 | C5: =B5+6 -> 46252 | D5: =SUMIFS('Daily Planner'!$G$4:$G$123,'Daily Planner'!$B$4:$B$123,">="&B5,'Daily Planner'!$B$4:$B$123,"<="&C5,'Daily Planner'!$H$4:$H$123,TRUE()) -> 0
A6: 3 | B6: 46253 | C6: =B6+6 -> 46259 | D6: =SUMIFS('Daily Planner'!$G$4:$G$123,'Daily Planner'!$B$4:$B$123,">="&B6,'Daily Planner'!$B$4:$B$123,"<="&C6,'Daily Planner'!$H$4:$H$123,TRUE()) -> 0
A7: 4 | B7: 46260 | C7: =B7+6 -> 46266 | D7: =SUMIFS('Daily Planner'!$G$4:$G$123,'Daily Planner'!$B$4:$B$123,">="&B7,'Daily Planner'!$B$4:$B$123,"<="&C7,'Daily Planner'!$H$4:$H$123,TRUE()) -> 0
A8: 5 | B8: 46267 | C8: =B8+6 -> 46273 | D8: =SUMIFS('Daily Planner'!$G$4:$G$123,'Daily Planner'!$B$4:$B$123,">="&B8,'Daily Planner'!$B$4:$B$123,"<="&C8,'Daily Planner'!$H$4:$H$123,TRUE()) -> 0
A9: 6 | B9: 46274 | C9: =B9+6 -> 46280 | D9: =SUMIFS('Daily Planner'!$G$4:$G$123,'Daily Planner'!$B$4:$B$123,">="&B9,'Daily Planner'!$B$4:$B$123,"<="&C9,'Daily Planner'!$H$4:$H$123,TRUE()) -> 0
A10: 7 | B10: 46281 | C10: =B10+6 -> 46287 | D10: =SUMIFS('Daily Planner'!$G$4:$G$123,'Daily Planner'!$B$4:$B$123,">="&B10,'Daily Planner'!$B$4:$B$123,"<="&C10,'Daily Planner'!$H$4:$H$123,TRUE()) -> 0
A11: 8 | B11: 46288 | C11: =B11+6 -> 46294 | D11: =SUMIFS('Daily Planner'!$G$4:$G$123,'Daily Planner'!$B$4:$B$123,">="&B11,'Daily Planner'!$B$4:$B$123,"<="&C11,'Daily Planner'!$H$4:$H$123,TRUE()) -> 0
A12: 9 | B12: 46295 | C12: =B12+6 -> 46301 | D12: =SUMIFS('Daily Planner'!$G$4:$G$123,'Daily Planner'!$B$4:$B$123,">="&B12,'Daily Planner'!$B$4:$B$123,"<="&C12,'Daily Planner'!$H$4:$H$123,TRUE()) -> 0
A13: 10 | B13: 46302 | C13: =B13+6 -> 46308 | D13: =SUMIFS('Daily Planner'!$G$4:$G$123,'Daily Planner'!$B$4:$B$123,">="&B13,'Daily Planner'!$B$4:$B$123,"<="&C13,'Daily Planner'!$H$4:$H$123,TRUE()) -> 0
A14: 11 | B14: 46309 | C14: =B14+6 -> 46315 | D14: =SUMIFS('Daily Planner'!$G$4:$G$123,'Daily Planner'!$B$4:$B$123,">="&B14,'Daily Planner'!$B$4:$B$123,"<="&C14,'Daily Planner'!$H$4:$H$123,TRUE()) -> 0
A15: 12 | B15: 46316 | C15: =B15+6 -> 46322 | D15: =SUMIFS('Daily Planner'!$G$4:$G$123,'Daily Planner'!$B$4:$B$123,">="&B15,'Daily Planner'!$B$4:$B$123,"<="&C15,'Daily Planner'!$H$4:$H$123,TRUE()) -> 0
... A21: 18 | B21: 46358 | C21: =B21+6 -> 46364 | D21: =SUMIFS('Daily Planner'!$G$4:$G$123,'Daily Planner'!$B$4:$B$123,">="&B21,'Daily Planner'!$B$4:$B$123,"<="&C21,'Daily Planner'!$H$4:$H$123,TRUE()) -> 0

Sheet Monthly Review
A1: Monthly Review
A2: Topics Completed now pulls automatically from every curriculum sheet's Date Completed column. Projects/Research/Interview Progress stay manual since those sheets don't track a completion date per spec.
A3: Month | B3: Topics Completed (auto) | C3: Projects | D3: Research | E3: Interview Progress | F3: Skills Improved | G3: Goals Next Month
A4: August 2026 | B4: =COUNTIFS('Python Advanced'!O5:O34,">="&DATE(2026,8,1),'Python Advanced'!O5:O34,"<="&DATE(2026,8,31))+COUNTIFS('Data Structures & Algorithms'!O5:O38,">="&DATE(2026,8,1),'Data Structures & Algorithms'!O5:O38,"<="&DATE(2026,8,31))+COUNTIFS('Operating Systems'!O5:O33,">="&DATE(2026,8,1),'Operating Systems'!O5:O33,"<="&DATE(2026,8,31))+COUNTIFS('Computer Networking'!O5:O29,">="&DATE(2026,8,1),'Computer Networking'!O5:O29,"<="&DATE(2026,8,31))+COUNTIFS(Databases!O5:O24,">="&DATE(2026,8,1),Databases!O5:O24,"<="&DATE(2026,8,31))+COUNTIFS(Mathematics!O5:O28,">="&DATE(2026,8,1),Mathematics!O5:O28,"<="&DATE(2026,8,31))+COUNTIFS('Machine Learning'!O5:O23,">="&DATE(2026,8,1),'Machine Learning'!O5:O23,"<="&DATE(2026,8,31))+COUNTIFS('Deep Learning'!O5:O23,">="&DATE(2026,8,1),'Deep Learning'!O5:O23,"<="&DATE(2026,8,31))+COUNTIFS('LLM Engineering'!O5:O37,">="&DATE(2026,8,1),'LLM Engineering'!O5:O37,"<="&DATE(2026,8,31))+COUNTIFS('CUDA & GPU Programming'!O5:O22,">="&DATE(2026,8,1),'CUDA & GPU Programming'!O5:O22,"<="&DATE(2026,8,31))+COUNTIFS('Distributed Systems'!O5:O29,">="&DATE(2026,8,1),'Distributed Systems'!O5:O29,"<="&DATE(2026,8,31)) -> 1
A5: September 2026 | B5: =COUNTIFS('Python Advanced'!O5:O34,">="&DATE(2026,9,1),'Python Advanced'!O5:O34,"<="&DATE(2026,9,30))+COUNTIFS('Data Structures & Algorithms'!O5:O38,">="&DATE(2026,9,1),'Data Structures & Algorithms'!O5:O38,"<="&DATE(2026,9,30))+COUNTIFS('Operating Systems'!O5:O33,">="&DATE(2026,9,1),'Operating Systems'!O5:O33,"<="&DATE(2026,9,30))+COUNTIFS('Computer Networking'!O5:O29,">="&DATE(2026,9,1),'Computer Networking'!O5:O29,"<="&DATE(2026,9,30))+COUNTIFS(Databases!O5:O24,">="&DATE(2026,9,1),Databases!O5:O24,"<="&DATE(2026,9,30))+COUNTIFS(Mathematics!O5:O28,">="&DATE(2026,9,1),Mathematics!O5:O28,"<="&DATE(2026,9,30))+COUNTIFS('Machine Learning'!O5:O23,">="&DATE(2026,9,1),'Machine Learning'!O5:O23,"<="&DATE(2026,9,30))+COUNTIFS('Deep Learning'!O5:O23,">="&DATE(2026,9,1),'Deep Learning'!O5:O23,"<="&DATE(2026,9,30))+COUNTIFS('LLM Engineering'!O5:O37,">="&DATE(2026,9,1),'LLM Engineering'!O5:O37,"<="&DATE(2026,9,30))+COUNTIFS('CUDA & GPU Programming'!O5:O22,">="&DATE(2026,9,1),'CUDA & GPU Programming'!O5:O22,"<="&DATE(2026,9,30))+COUNTIFS('Distributed Systems'!O5:O29,">="&DATE(2026,9,1),'Distributed Systems'!O5:O29,"<="&DATE(2026,9,30)) -> 0
A6: October 2026 | B6: =COUNTIFS('Python Advanced'!O5:O34,">="&DATE(2026,10,1),'Python Advanced'!O5:O34,"<="&DATE(2026,10,31))+COUNTIFS('Data Structures & Algorithms'!O5:O38,">="&DATE(2026,10,1),'Data Structures & Algorithms'!O5:O38,"<="&DATE(2026,10,31))+COUNTIFS('Operating Systems'!O5:O33,">="&DATE(2026,10,1),'Operating Systems'!O5:O33,"<="&DATE(2026,10,31))+COUNTIFS('Computer Networking'!O5:O29,">="&DATE(2026,10,1),'Computer Networking'!O5:O29,"<="&DATE(2026,10,31))+COUNTIFS(Databases!O5:O24,">="&DATE(2026,10,1),Databases!O5:O24,"<="&DATE(2026,10,31))+COUNTIFS(Mathematics!O5:O28,">="&DATE(2026,10,1),Mathematics!O5:O28,"<="&DATE(2026,10,31))+COUNTIFS('Machine Learning'!O5:O23,">="&DATE(2026,10,1),'Machine Learning'!O5:O23,"<="&DATE(2026,10,31))+COUNTIFS('Deep Learning'!O5:O23,">="&DATE(2026,10,1),'Deep Learning'!O5:O23,"<="&DATE(2026,10,31))+COUNTIFS('LLM Engineering'!O5:O37,">="&DATE(2026,10,1),'LLM Engineering'!O5:O37,"<="&DATE(2026,10,31))+COUNTIFS('CUDA & GPU Programming'!O5:O22,">="&DATE(2026,10,1),'CUDA & GPU Programming'!O5:O22,"<="&DATE(2026,10,31))+COUNTIFS('Distributed Systems'!O5:O29,">="&DATE(2026,10,1),'Distributed Systems'!O5:O29,"<="&DATE(2026,10,31)) -> 0
A7: November 2026 | B7: =COUNTIFS('Python Advanced'!O5:O34,">="&DATE(2026,11,1),'Python Advanced'!O5:O34,"<="&DATE(2026,11,30))+COUNTIFS('Data Structures & Algorithms'!O5:O38,">="&DATE(2026,11,1),'Data Structures & Algorithms'!O5:O38,"<="&DATE(2026,11,30))+COUNTIFS('Operating Systems'!O5:O33,">="&DATE(2026,11,1),'Operating Systems'!O5:O33,"<="&DATE(2026,11,30))+COUNTIFS('Computer Networking'!O5:O29,">="&DATE(2026,11,1),'Computer Networking'!O5:O29,"<="&DATE(2026,11,30))+COUNTIFS(Databases!O5:O24,">="&DATE(2026,11,1),Databases!O5:O24,"<="&DATE(2026,11,30))+COUNTIFS(Mathematics!O5:O28,">="&DATE(2026,11,1),Mathematics!O5:O28,"<="&DATE(2026,11,30))+COUNTIFS('Machine Learning'!O5:O23,">="&DATE(2026,11,1),'Machine Learning'!O5:O23,"<="&DATE(2026,11,30))+COUNTIFS('Deep Learning'!O5:O23,">="&DATE(2026,11,1),'Deep Learning'!O5:O23,"<="&DATE(2026,11,30))+COUNTIFS('LLM Engineering'!O5:O37,">="&DATE(2026,11,1),'LLM Engineering'!O5:O37,"<="&DATE(2026,11,30))+COUNTIFS('CUDA & GPU Programming'!O5:O22,">="&DATE(2026,11,1),'CUDA & GPU Programming'!O5:O22,"<="&DATE(2026,11,30))+COUNTIFS('Distributed Systems'!O5:O29,">="&DATE(2026,11,1),'Distributed Systems'!O5:O29,"<="&DATE(2026,11,30)) -> 0
A8: December 2026 | B8: =COUNTIFS('Python Advanced'!O5:O34,">="&DATE(2026,12,1),'Python Advanced'!O5:O34,"<="&DATE(2026,12,31))+COUNTIFS('Data Structures & Algorithms'!O5:O38,">="&DATE(2026,12,1),'Data Structures & Algorithms'!O5:O38,"<="&DATE(2026,12,31))+COUNTIFS('Operating Systems'!O5:O33,">="&DATE(2026,12,1),'Operating Systems'!O5:O33,"<="&DATE(2026,12,31))+COUNTIFS('Computer Networking'!O5:O29,">="&DATE(2026,12,1),'Computer Networking'!O5:O29,"<="&DATE(2026,12,31))+COUNTIFS(Databases!O5:O24,">="&DATE(2026,12,1),Databases!O5:O24,"<="&DATE(2026,12,31))+COUNTIFS(Mathematics!O5:O28,">="&DATE(2026,12,1),Mathematics!O5:O28,"<="&DATE(2026,12,31))+COUNTIFS('Machine Learning'!O5:O23,">="&DATE(2026,12,1),'Machine Learning'!O5:O23,"<="&DATE(2026,12,31))+COUNTIFS('Deep Learning'!O5:O23,">="&DATE(2026,12,1),'Deep Learning'!O5:O23,"<="&DATE(2026,12,31))+COUNTIFS('LLM Engineering'!O5:O37,">="&DATE(2026,12,1),'LLM Engineering'!O5:O37,"<="&DATE(2026,12,31))+COUNTIFS('CUDA & GPU Programming'!O5:O22,">="&DATE(2026,12,1),'CUDA & GPU Programming'!O5:O22,"<="&DATE(2026,12,31))+COUNTIFS('Distributed Systems'!O5:O29,">="&DATE(2026,12,1),'Distributed Systems'!O5:O29,"<="&DATE(2026,12,31)) -> 0

Sheet Revision Planner
A1: Revision Planner
A2: Spaced-repetition schedule: 1 -> 3 -> 7 -> 14 -> 30 -> 90 -> 365 days. Each curriculum sheet computes its own Revision Date from Date Completed + Revision Stage; this sheet rolls those up and flags overdue items.
A3: Subject | B3: Total Topics | C3: Completed | D3: % Complete | E3: Overdue Revisions | F3: Due Within 3 Days
A4: Python Advanced | B4: =SUMPRODUCT(COUNTIF('Python Advanced'!A5:A34,{"Completed","In Progress","Not Started","Research","Project","Optional"})) -> 26 | C4: =COUNTIF('Python Advanced'!A5:A34,"Completed") -> 2 | D4: =IF(B4=0,0,ROUND(C4/B4*100,0)) -> 8 | E4: =COUNTIFS('Python Advanced'!Q5:Q34,"<"&TODAY(),'Python Advanced'!Q5:Q34,"<>") -> 0 | F4: =COUNTIFS('Python Advanced'!Q5:Q34,">="&TODAY(),'Python Advanced'!Q5:Q34,"<="&TODAY()+3) -> 0
A5: Data Structures & Algorithms | B5: =SUMPRODUCT(COUNTIF('Data Structures & Algorithms'!A5:A38,{"Completed","In Progress","Not Started","Research","Project","Optional"})) -> 29 | C5: =COUNTIF('Data Structures & Algorithms'!A5:A38,"Completed") -> 0 | D5: =IF(B5=0,0,ROUND(C5/B5*100,0)) -> 0 | E5: =COUNTIFS('Data Structures & Algorithms'!Q5:Q38,"<"&TODAY(),'Data Structures & Algorithms'!Q5:Q38,"<>") -> 0 | F5: =COUNTIFS('Data Structures & Algorithms'!Q5:Q38,">="&TODAY(),'Data Structures & Algorithms'!Q5:Q38,"<="&TODAY()+3) -> 0
A6: Operating Systems | B6: =SUMPRODUCT(COUNTIF('Operating Systems'!A5:A33,{"Completed","In Progress","Not Started","Research","Project","Optional"})) -> 25 | C6: =COUNTIF('Operating Systems'!A5:A33,"Completed") -> 0 | D6: =IF(B6=0,0,ROUND(C6/B6*100,0)) -> 0 | E6: =COUNTIFS('Operating Systems'!Q5:Q33,"<"&TODAY(),'Operating Systems'!Q5:Q33,"<>") -> 0 | F6: =COUNTIFS('Operating Systems'!Q5:Q33,">="&TODAY(),'Operating Systems'!Q5:Q33,"<="&TODAY()+3) -> 0
A7: Computer Networking | B7: =SUMPRODUCT(COUNTIF('Computer Networking'!A5:A29,{"Completed","In Progress","Not Started","Research","Project","Optional"})) -> 21 | C7: =COUNTIF('Computer Networking'!A5:A29,"Completed") -> 0 | D7: =IF(B7=0,0,ROUND(C7/B7*100,0)) -> 0 | E7: =COUNTIFS('Computer Networking'!Q5:Q29,"<"&TODAY(),'Computer Networking'!Q5:Q29,"<>") -> 0 | F7: =COUNTIFS('Computer Networking'!Q5:Q29,">="&TODAY(),'Computer Networking'!Q5:Q29,"<="&TODAY()+3) -> 0
A8: Databases | B8: =SUMPRODUCT(COUNTIF(Databases!A5:A24,{"Completed","In Progress","Not Started","Research","Project","Optional"})) -> 17 | C8: =COUNTIF(Databases!A5:A24,"Completed") -> 0 | D8: =IF(B8=0,0,ROUND(C8/B8*100,0)) -> 0 | E8: =COUNTIFS(Databases!Q5:Q24,"<"&TODAY(),Databases!Q5:Q24,"<>") -> 0 | F8: =COUNTIFS(Databases!Q5:Q24,">="&TODAY(),Databases!Q5:Q24,"<="&TODAY()+3) -> 0
A9: Mathematics | B9: =SUMPRODUCT(COUNTIF(Mathematics!A5:A28,{"Completed","In Progress","Not Started","Research","Project","Optional"})) -> 21 | C9: =COUNTIF(Mathematics!A5:A28,"Completed") -> 0 | D9: =IF(B9=0,0,ROUND(C9/B9*100,0)) -> 0 | E9: =COUNTIFS(Mathematics!Q5:Q28,"<"&TODAY(),Mathematics!Q5:Q28,"<>") -> 0 | F9: =COUNTIFS(Mathematics!Q5:Q28,">="&TODAY(),Mathematics!Q5:Q28,"<="&TODAY()+3) -> 0
A10: Machine Learning | B10: =SUMPRODUCT(COUNTIF('Machine Learning'!A5:A23,{"Completed","In Progress","Not Started","Research","Project","Optional"})) -> 16 | C10: =COUNTIF('Machine Learning'!A5:A23,"Completed") -> 0 | D10: =IF(B10=0,0,ROUND(C10/B10*100,0)) -> 0 | E10: =COUNTIFS('Machine Learning'!Q5:Q23,"<"&TODAY(),'Machine Learning'!Q5:Q23,"<>") -> 0 | F10: =COUNTIFS('Machine Learning'!Q5:Q23,">="&TODAY(),'Machine Learning'!Q5:Q23,"<="&TODAY()+3) -> 0
A11: Deep Learning | B11: =SUMPRODUCT(COUNTIF('Deep Learning'!A5:A23,{"Completed","In Progress","Not Started","Research","Project","Optional"})) -> 16 | C11: =COUNTIF('Deep Learning'!A5:A23,"Completed") -> 0 | D11: =IF(B11=0,0,ROUND(C11/B11*100,0)) -> 0 | E11: =COUNTIFS('Deep Learning'!Q5:Q23,"<"&TODAY(),'Deep Learning'!Q5:Q23,"<>") -> 0 | F11: =COUNTIFS('Deep Learning'!Q5:Q23,">="&TODAY(),'Deep Learning'!Q5:Q23,"<="&TODAY()+3) -> 0
A12: LLM Engineering | B12: =SUMPRODUCT(COUNTIF('LLM Engineering'!A5:A37,{"Completed","In Progress","Not Started","Research","Project","Optional"})) -> 29 | C12: =COUNTIF('LLM Engineering'!A5:A37,"Completed") -> 0 | D12: =IF(B12=0,0,ROUND(C12/B12*100,0)) -> 0 | E12: =COUNTIFS('LLM Engineering'!Q5:Q37,"<"&TODAY(),'LLM Engineering'!Q5:Q37,"<>") -> 0 | F12: =COUNTIFS('LLM Engineering'!Q5:Q37,">="&TODAY(),'LLM Engineering'!Q5:Q37,"<="&TODAY()+3) -> 0
A13: CUDA & GPU Programming | B13: =SUMPRODUCT(COUNTIF('CUDA & GPU Programming'!A5:A22,{"Completed","In Progress","Not Started","Research","Project","Optional"})) -> 15 | C13: =COUNTIF('CUDA & GPU Programming'!A5:A22,"Completed") -> 0 | D13: =IF(B13=0,0,ROUND(C13/B13*100,0)) -> 0 | E13: =COUNTIFS('CUDA & GPU Programming'!Q5:Q22,"<"&TODAY(),'CUDA & GPU Programming'!Q5:Q22,"<>") -> 0 | F13: =COUNTIFS('CUDA & GPU Programming'!Q5:Q22,">="&TODAY(),'CUDA & GPU Programming'!Q5:Q22,"<="&TODAY()+3) -> 0
A14: Distributed Systems | B14: =SUMPRODUCT(COUNTIF('Distributed Systems'!A5:A29,{"Completed","In Progress","Not Started","Research","Project","Optional"})) -> 22 | C14: =COUNTIF('Distributed Systems'!A5:A29,"Completed") -> 0 | D14: =IF(B14=0,0,ROUND(C14/B14*100,0)) -> 0 | E14: =COUNTIFS('Distributed Systems'!Q5:Q29,"<"&TODAY(),'Distributed Systems'!Q5:Q29,"<>") -> 0 | F14: =COUNTIFS('Distributed Systems'!Q5:Q29,">="&TODAY(),'Distributed Systems'!Q5:Q29,"<="&TODAY()+3) -> 0
A15: TOTAL | B15: =SUM(B4:B14) -> 237 | C15: =SUM(C4:C14) -> 2 | D15: =IF(B15=0,0,ROUND(C15/B15*100,0)) -> 1 | E15: =SUM(E4:E14) -> 0 | F15: =SUM(F4:F14) -> 0

Sheet Python Advanced
A1: Python Advanced
A2: Intermediate->expert CPython internals, concurrency, and native performance. No beginner syntax topics.
A3: Sheet Progress — 26 topics total | Q3: =ROUND(COUNTIF(A5:A34,"Completed")/SUMPRODUCT(COUNTIF(A5:A34,{"Completed","In Progress","Not Started","Research","Project","Optional"}))*100,0) -> 8
A4: Status | B4: Topic | C4: Subtopic | D4: Difficulty | E4: Prerequisites | F4: Learning Goal | G4: Est. Hours | H4: Best YouTube Resource | I4: Best Reading | J4: Official Documentation | K4: Coding Exercise | L4: Mini Project | M4: Interview Questions | N4: Notes | O4: Date Completed | P4: Revision Stage | Q4: Revision Date
A5: CPython Internals & Memory Model
A6: Completed | B6: CPython Internals | C6: PyObject struct & object layout | D6: Advanced | E6: C basics, Python fluency | F6: Understand how every Python object is represented in memory via PyObject/PyVarObject. | G6: 3 | H6: CPython Internals - James Powell (PyData) | I6: 'CPython Internals' book by Anthony Shaw (Ch.1-3) | J6: docs.python.org/3/c-api/structures.html | K6: Write a C extension that inspects an object's ob_refcnt and ob_type | L6: Build a memory-layout visualizer using ctypes | M6: What is the difference between PyObject and PyVarObject? | Why does every Python object carry a refcount? | N6: Foundation for everything else in this section. | O6: 46239 | P6: 0 | Q6: =IF(OR(O6="",P6=0),"",O6+CHOOSE(P6,1,3,7,14,30,90,365))
A7: Not Started | B7: Python Memory Model | C7: Private heap & pymalloc arenas | D7: Advanced | E7: CPython Internals basics | F7: Understand pymalloc's arena/pool/block allocator design for small objects. | G7: 3 | H7: Real Python - Memory Management in Python | I7: docs.python.org/3/c-api/memory.html | J7: docs.python.org/3/c-api/memory.html | K7: Use tracemalloc to profile allocations of a small script | L7: Build a script that visualizes allocation size distributions | M7: Why does CPython use its own allocator instead of malloc directly? | What is a pymalloc arena? | N7: tracemalloc is the practical entry point. | P7: 0 | Q7: =IF(OR(O7="",P7=0),"",O7+CHOOSE(P7,1,3,7,14,30,90,365))
A8: Not Started | B8: Reference Counting | C8: Refcounting mechanics & INCREF/DECREF | D8: Advanced | E8: CPython Internals | F8: Trace how Py_INCREF/Py_DECREF drive object lifetime. | G8: 2 | H8: CPython Internals - Refcounting explained (Anthony Shaw talk) | I8: 'CPython Internals' book Ch.4 | J8: docs.python.org/3/c-api/refcounting.html | K8: Use sys.getrefcount to trace an object across scopes | L8: N/A | M8: Why can sys.getrefcount overcount by one? | What happens on refcount reaching zero? | N8: Classic gotcha: getrefcount's own argument passing adds a reference. | P8: 0 | Q8: =IF(OR(O8="",P8=0),"",O8+CHOOSE(P8,1,3,7,14,30,90,365))
A9: Not Started | B9: Garbage Collection | C9: Generational GC & cycle detection | D9: Advanced | E9: Reference Counting | F9: Understand the 3-generation cyclic GC that supplements refcounting. | G9: 3 | H9: Real Python - Garbage Collection in Python | I9: docs.python.org/3/library/gc.html | J9: docs.python.org/3/library/gc.html | K9: Create and detect a reference cycle with gc.get_objects() | L9: Build a tool that flags reference cycles in a codebase | M9: Why is cyclic GC needed if refcounting exists? | What are generations 0/1/2 for? | N9: __del__ and cycles historically interacted badly pre-3.4. | P9: 0 | Q9: =IF(OR(O9="",P9=0),"",O9+CHOOSE(P9,1,3,7,14,30,90,365))
A10: Not Started | B10: Descriptors | C10: Data vs non-data descriptors, __get__/__set__ | D10: Advanced | E10: OOP fundamentals | F10: Master the descriptor protocol that underlies properties, methods, and slots. | G10: 3 | H10: Real Python - Descriptors | I10: docs.python.org/3/howto/descriptor.html | J10: docs.python.org/3/reference/datamodel.html#descriptors | K10: Implement a validated-attribute descriptor from scratch | L10: Build a typed-field ORM-style mini library using descriptors | M10: What's the precedence order between instance __dict__ and a data descriptor? | How does @property use descriptors? | N10: Understanding this unlocks how Django/SQLAlchemy fields work. | P10: 0 | Q10: =IF(OR(O10="",P10=0),"",O10+CHOOSE(P10,1,3,7,14,30,90,365))
A11: Not Started | B11: Decorators Internals | C11: Closures, functools.wraps, decorator factories | D11: Advanced | E11: Descriptors | F11: Go beyond syntax to understand closures and metadata preservation in decorators. | G11: 2 | H11: mCoding - Python Decorators | I11: Real Python - Primer on Python Decorators | J11: docs.python.org/3/library/functools.html#functools.wraps | K11: Write a parametrized retry decorator with backoff | L11: Build a timing/profiling decorator library | M11: Why does functools.wraps matter? | How do class-based decorators differ from function-based? | N11: Watch for late-binding closures in loops. | P11: 0 | Q11: =IF(OR(O11="",P11=0),"",O11+CHOOSE(P11,1,3,7,14,30,90,365))
A12: Not Started | B12: Metaclasses | C12: type(), __new__ vs __init__, metaclass conflicts | D12: Expert | E12: Descriptors, OOP | F12: Understand how classes themselves are instances of metaclasses. | G12: 4 | H12: mCoding - Metaclasses Explained | I12: Real Python - Python Metaclasses | J12: docs.python.org/3/reference/datamodel.html#metaclasses | K12: Build a metaclass that auto-registers subclasses | L12: Implement a simple ORM base using a metaclass | M12: When would you use __init_subclass__ instead of a metaclass? | What problem do ABCMeta and metaclasses solve? | N12: Prefer __init_subclass__ / __set_name__ when possible; metaclasses are a last resort. | P12: 0 | Q12: =IF(OR(O12="",P12=0),"",O12+CHOOSE(P12,1,3,7,14,30,90,365))
A13: Not Started | B13: Slots | C13: __slots__ memory savings & limitations | D13: Advanced | E13: Descriptors | F13: Understand how __slots__ removes per-instance __dict__ to save memory. | G13: 1 | H13: mCoding - __slots__ Explained | I13: Real Python - Python __slots__ | J13: docs.python.org/3/reference/datamodel.html#slots | K13: Benchmark memory usage of a class with vs without __slots__ | L13: N/A | M13: Why can't you use __slots__ with multiple inheritance easily? | What breaks when you add __slots__? | N13: Big win for millions of small objects (e.g. graph nodes). | P13: 0 | Q13: =IF(OR(O13="",P13=0),"",O13+CHOOSE(P13,1,3,7,14,30,90,365))
A14: Concurrency & Parallelism
A15: Completed | B15: GIL | C15: Global Interpreter Lock mechanics & 3.13 free-threading | D15: Expert | E15: CPython Internals | F15: Understand why the GIL exists and what the no-GIL (PEP 703) build changes. | G15: 4 | H15: David Beazley - Understanding the GIL | I15: Real Python - What is the GIL | J15: docs.python.org/3/glossary.html#term-global-interpreter-lock | K15: Benchmark CPU-bound threading vs multiprocessing | L15: N/A | M15: Why doesn't the GIL block I/O-bound concurrency? | What does PEP 703 change? | N15: Directly relevant to inference-server throughput design. | P15: 2 | Q15: =IF(OR(O15="",P15=0),"",O15+CHOOSE(P15,1,3,7,14,30,90,365))
A16: Not Started | B16: Multiprocessing Internals | C16: Process pools, pickling, shared memory | D16: Advanced | E16: GIL | F16: Understand fork/spawn start methods and IPC costs in multiprocessing. | G16: 3 | H16: Real Python - Multiprocessing in Python | I16: docs.python.org/3/library/multiprocessing.html | J16: docs.python.org/3/library/multiprocessing.shared_memory.html | K16: Build a producer-consumer pipeline using multiprocessing.Queue | L16: Parallelize a CPU-bound data preprocessing pipeline | M16: Why is spawn safer than fork on macOS/Windows? | When would you use shared_memory over a Queue? | N16: Pickling overhead is the usual bottleneck for large tensors. | P16: 0 | Q16: =IF(OR(O16="",P16=0),"",O16+CHOOSE(P16,1,3,7,14,30,90,365))
A17: Not Started | B17: Threading | C17: Thread pools, locks, condition variables | D17: Advanced | E17: GIL | F17: Master thread synchronization primitives beyond basic locks. | G17: 3 | H17: Corey Schafer - Threading Tutorial | I17: Real Python - Intro to Threading | J17: docs.python.org/3/library/threading.html | K17: Implement a bounded worker pool with a Condition variable | L17: N/A | M17: When is a RLock needed instead of a Lock? | What's a thundering herd and how do Conditions avoid it? | N17: Best for I/O-bound work given the GIL. | P17: 0 | Q17: =IF(OR(O17="",P17=0),"",O17+CHOOSE(P17,1,3,7,14,30,90,365))
A18: Not Started | B18: Asyncio Internals | C18: Event loop, tasks, futures | D18: Expert | E18: Threading | F18: Understand how the asyncio event loop schedules coroutines via a select/epoll loop. | G18: 4 | H18: David Beazley - Build Your Own Async | I18: Real Python - Async IO in Python | J18: docs.python.org/3/library/asyncio-eventloop.html | K18: Implement a minimal event loop from scratch with generators | L18: Build an async rate-limited API client | M18: What's the difference between a Task and a Future? | How does await suspend/resume a coroutine? | N18: Core to understanding FastAPI's request handling model. | P18: 0 | Q18: =IF(OR(O18="",P18=0),"",O18+CHOOSE(P18,1,3,7,14,30,90,365))
A19: Not Started | B19: Selectors | C19: selectors module & epoll/kqueue abstraction | D19: Advanced | E19: Asyncio Internals | F19: Understand the OS-level readiness notification asyncio is built on. | G19: 2 | H19: Real Python - Selectors module walkthrough | I19: docs.python.org/3/library/selectors.html | J19: docs.python.org/3/library/selectors.html | K19: Build a simple echo server using selectors directly (no asyncio) | L19: N/A | M19: Why is epoll preferred over select() at scale? | What is level-triggered vs edge-triggered readiness? | N19: This is the layer directly beneath asyncio's event loop. | P19: 0 | Q19: =IF(OR(O19="",P19=0),"",O19+CHOOSE(P19,1,3,7,14,30,90,365))
A20: Not Started | B20: Concurrency Models | C20: Choosing threads vs processes vs asyncio | D20: Advanced | E20: GIL, Asyncio Internals | F20: Build intuition for choosing the right concurrency model for a workload. | G20: 2 | H20: Anthony Explains - Concurrency in Python | I20: Real Python - Speed Up Python with Concurrency | J20: docs.python.org/3/library/concurrency.html | K20: Benchmark the same workload under threading/multiprocessing/asyncio | L20: N/A | M20: How do you choose between threads, processes, and asyncio for an ML inference server? | N20: Common system-design interview follow-up. | P20: 0 | Q20: =IF(OR(O20="",P20=0),"",O20+CHOOSE(P20,1,3,7,14,30,90,365))
A21: Language Internals & Bytecode
A22: Not Started | B22: Bytecode | C22: dis module, stack-based VM execution | D22: Advanced | E22: CPython Internals | F22: Read and interpret CPython bytecode to understand execution cost. | G22: 3 | H22: mCoding - Reading Python Bytecode | I22: Real Python - Bytecode intro | J22: docs.python.org/3/library/dis.html | K22: Use dis.dis to compare bytecode for a for-loop vs a list comprehension | L22: N/A | M22: Why are list comprehensions often faster than equivalent for-loops? | What is a stack-based VM? | N22: Useful for micro-optimization interview questions. | P22: 0 | Q22: =IF(OR(O22="",P22=0),"",O22+CHOOSE(P22,1,3,7,14,30,90,365))
A23: Not Started | B23: Python Compiler | C23: AST, compile phases, peephole optimizer | D23: Expert | E23: Bytecode | F23: Trace source code from AST to bytecode through the compiler pipeline. | G23: 3 | H23: CPython compiler pipeline talk - James Powell | I23: 'CPython Internals' Ch.8-9 | J23: docs.python.org/3/library/ast.html | K23: Write an AST transformer that rewrites a simple expression | L23: N/A | M23: What are the compilation stages from source to bytecode? | What does the peephole optimizer do? | N23: Powers tools like Bandit, and custom linters. | P23: 0 | Q23: =IF(OR(O23="",P23=0),"",O23+CHOOSE(P23,1,3,7,14,30,90,365))
A24: Not Started | B24: Context Managers | C24: __enter__/__exit__, contextlib, ExitStack | D24: Advanced | E24: Descriptors | F24: Master resource-management patterns beyond basic 'with' usage. | G24: 2 | H24: mCoding - Context Managers | I24: Real Python - Context Managers and Python's with Statement | J24: docs.python.org/3/library/contextlib.html | K24: Build a nested-resource manager using contextlib.ExitStack | L24: Build a DB transaction context manager with rollback on exception | M24: How does __exit__'s return value suppress exceptions? | What problem does ExitStack solve? | N24: ExitStack is underused and great for dynamic resource counts. | P24: 0 | Q24: =IF(OR(O24="",P24=0),"",O24+CHOOSE(P24,1,3,7,14,30,90,365))
A25: Not Started | B25: Type Hints | C25: Structural typing, Protocol, overload | D25: Advanced | E25: Python fluency | F25: Use the typing module for structural (duck) typing contracts. | G25: 2 | H25: mCoding - Python Type Hints | I25: Real Python - Type Checking in Python | J25: docs.python.org/3/library/typing.html | K25: Define a Protocol for a 'Trainable' interface and type-check with mypy | L25: N/A | M25: What's the difference between nominal and structural typing? | When would you use @overload? | N25: Protocols are close to Go/TS-style interfaces. | P25: 0 | Q25: =IF(OR(O25="",P25=0),"",O25+CHOOSE(P25,1,3,7,14,30,90,365))
A26: Not Started | B26: Generics | C26: TypeVar, Generic classes, PEP 695 syntax | D26: Advanced | E26: Type Hints | F26: Write reusable generic classes and functions with proper variance. | G26: 2 | H26: mCoding - Generics in Python | I26: Real Python - Generics | J26: docs.python.org/3/library/typing.html#generics | K26: Implement a generic Repository[T] class with mypy strict mode | L26: N/A | M26: What is covariance vs contravariance in generics? | How does PEP 695 simplify generic syntax (3.12+)? | N26: PEP 695 (3.12) meaningfully cleans up old TypeVar boilerplate. | P26: 0 | Q26: =IF(OR(O26="",P26=0),"",O26+CHOOSE(P26,1,3,7,14,30,90,365))
A27: Not Started | B27: Profiling | C27: cProfile, py-spy, line_profiler | D27: Advanced | E27: Python fluency | F27: Profile CPU-bound Python code and read flamegraphs. | G27: 3 | H27: Real Python - Profiling Python Code | I27: 'High Performance Python' Ch.2 (Gorelick & Ozsvath) | J27: docs.python.org/3/library/profile.html | K27: Profile a slow data-pipeline script and produce a flamegraph with py-spy | L27: Optimize a real script from 10x profiling findings | M27: What's the overhead difference between cProfile and py-spy? | When would you reach for line_profiler? | N27: py-spy can attach to a running production process with no code changes. | P27: 0 | Q27: =IF(OR(O27="",P27=0),"",O27+CHOOSE(P27,1,3,7,14,30,90,365))
A28: Not Started | B28: Optimization | C28: Algorithmic vs micro-optimization, caching | D28: Advanced | E28: Profiling | F28: Prioritize optimization effort using profiling data, not intuition. | G28: 2 | H28: Real Python - Python Performance Optimization | I28: 'High Performance Python' Ch.1 | J28: docs.python.org/3/library/functools.html#functools.lru_cache | K28: Apply lru_cache and measure the speedup on a recursive function | L28: N/A | M28: Why should you always profile before optimizing? | What's the tradeoff of lru_cache's memory use? | N28: Premature optimization is still the classic interview trap. | P28: 0 | Q28: =IF(OR(O28="",P28=0),"",O28+CHOOSE(P28,1,3,7,14,30,90,365))
A29: C Extensions & Native Performance
A30: Not Started | B30: C Extensions | C30: Writing a CPython C extension module | D30: Expert | E30: CPython Internals, C | F30: Write a native extension exposing a C function to Python. | G30: 5 | H30: Real Python - Building a C Extension | I30: 'CPython Internals' Ch.15 | J30: docs.python.org/3/extending/extending.html | K30: Write and build a C extension that speeds up a hot loop | L30: Port a slow pure-Python function to a C extension and benchmark | M30: What's the GIL's role when calling into a C extension? | How do you release the GIL in C code (Py_BEGIN_ALLOW_THREADS)? | N30: Releasing the GIL in C extensions is key for true parallelism. | P30: 0 | Q30: =IF(OR(O30="",P30=0),"",O30+CHOOSE(P30,1,3,7,14,30,90,365))
A31: Not Started | B31: Cython | C31: Typed Cython, cdef, memoryviews | D31: Advanced | E31: C Extensions basics | F31: Use Cython to compile typed Python-like code to C for speed. | G31: 4 | H31: Cython official tutorial (conference talks) | I31: 'Cython: A Guide for Python Programmers' (Smith) | J31: cython.readthedocs.io | K31: Cythonize a numeric hot loop and benchmark against pure Python/NumPy | L31: Speed up a data-preprocessing step with typed Cython | M31: What does 'cdef' buy you over a plain Python function? | How do memoryviews avoid copy overhead? | N31: Cython is the pragmatic middle ground before dropping to raw C. | P31: 0 | Q31: =IF(OR(O31="",P31=0),"",O31+CHOOSE(P31,1,3,7,14,30,90,365))
A32: Not Started | B32: PyBind11 | C32: Exposing C++ to Python, type casting | D32: Advanced | E32: C++ basics, C Extensions | F32: Bind C++ classes/functions into Python using pybind11. | G32: 4 | H32: pybind11 official walkthrough (conference talks) | I32: pybind11 documentation - First Steps | J32: pybind11.readthedocs.io | K32: Bind a small C++ class (e.g. a KV cache) to Python with pybind11 | L32: Wrap a C++ inference kernel and call it from Python | M32: How does pybind11 handle Python/C++ object lifetime? | Why is pybind11 preferred over raw CPython C-API for C++? | N32: This is exactly how PyTorch exposes its C++ core to Python. | P32: 0 | Q32: =IF(OR(O32="",P32=0),"",O32+CHOOSE(P32,1,3,7,14,30,90,365))
A33: Not Started | B33: NumPy Internals | C33: ndarray memory layout, strides, broadcasting | D33: Advanced | E33: C Extensions | F33: Understand strided memory layout and how broadcasting avoids copies. | G33: 3 | H33: Enthought - NumPy Internals | I33: 'From Python to NumPy' (Rougier, free online book) | J33: numpy.org/doc/stable/reference/internals.html | K33: Write a broadcasting rule checker from scratch and compare to NumPy's | L33: N/A | M33: What are strides and why do they make transpose free? | How does broadcasting decide compatible shapes? | N33: Foundational for reasoning about tensor ops performance. | P33: 0 | Q33: =IF(OR(O33="",P33=0),"",O33+CHOOSE(P33,1,3,7,14,30,90,365))
A34: Not Started | B34: PyTorch Internals | C34: Tensor storage, autograd graph, dispatcher | D34: Expert | E34: NumPy Internals | F34: Understand how PyTorch tensors, storage, and autograd tape fit together. | G34: 5 | H34: Edward Yang - PyTorch Internals talk | I34: 'PyTorch Internals' blog series - Edward Yang | J34: pytorch.org/docs/stable/notes/extending.html | K34: Trace a tensor operation through the dispatcher using torch's debug logging | L34: Implement a custom autograd.Function with backward pass | M34: What is the difference between a Tensor and its Storage? | How does the dispatcher route an op to a CPU/CUDA kernel? | N34: Directly relevant to writing custom CUDA-backed PyTorch ops. | P34: 0 | Q34: =IF(OR(O34="",P34=0),"",O34+CHOOSE(P34,1,3,7,14,30,90,365))

Sheet Data Structures & Algorithms
A1: Data Structures & Algorithms
A2: Advanced patterns and structures for coding interviews and systems-adjacent problem solving.
A3: Sheet Progress — 29 topics total | Q3: =ROUND(COUNTIF(A5:A38,"Completed")/SUMPRODUCT(COUNTIF(A5:A38,{"Completed","In Progress","Not Started","Research","Project","Optional"}))*100,0) -> 0
A4: Status | B4: Topic | C4: Subtopic | D4: Difficulty | E4: Prerequisites | F4: Learning Goal | G4: Est. Hours | H4: Best YouTube Resource | I4: Best Reading | J4: Official Documentation | K4: Coding Exercise | L4: Mini Project | M4: Interview Questions | N4: Notes | O4: Date Completed | P4: Revision Stage | Q4: Revision Date
A5: Arrays, Bit Manipulation & Searching
A6: Not Started | B6: Advanced Arrays | C6: In-place rotation, Dutch National Flag, cyclic sort | D6: Advanced | E6: Arrays basics | F6: Master in-place array manipulation patterns that avoid O(n) extra space. | G6: 2 | H6: NeetCode - Array patterns playlist | I6: 'Elements of Programming Interviews' Ch.5 | J6: N/A (pattern-based, no single doc) | K6: LeetCode 75 - Sort Colors (Dutch flag) | L6: N/A | M6: How does cyclic sort find missing numbers in O(1) space? | Why does the Dutch flag algorithm need 3 pointers? | N6: Pattern: LeetCode 41, 442, 448 all reuse cyclic sort. | P6: 0 | Q6: =IF(OR(O6="",P6=0),"",O6+CHOOSE(P6,1,3,7,14,30,90,365))
A7: Not Started | B7: Bit Manipulation | C7: XOR tricks, bitmasking, popcount | D7: Advanced | E7: Binary basics | F7: Use bitwise operators for O(1) space state tracking and fast arithmetic. | G7: 3 | H7: NeetCode - Bit Manipulation playlist | I7: 'Hacker's Delight' Ch.2 (Warren) | J7: docs.python.org/3/library/stdtypes.html#bitwise-operations-on-integer-types | K7: LeetCode 136 - Single Number, LeetCode 78 - Subsets via bitmask | L7: Build a bitmask-based DP solver for a small TSP instance | M7: Why does XOR-ing all elements find the unique one? | How do you enumerate all subsets using bitmasks? | N7: Bitmask DP shows up constantly in 'assign N items to K groups' problems. | P7: 0 | Q7: =IF(OR(O7="",P7=0),"",O7+CHOOSE(P7,1,3,7,14,30,90,365))
A8: Not Started | B8: Binary Search | C8: Search space reduction, binary search on answer | D8: Advanced | E8: Sorted arrays | F8: Recognize when a problem's answer space (not just an array) is monotonic and binary-searchable. | G8: 3 | H8: NeetCode - Binary Search playlist | I8: 'Elements of Programming Interviews' Ch.7 | J8: N/A | K8: LeetCode 875 - Koko Eating Bananas (binary search on answer) | L8: N/A | M8: How do you binary search on a monotonic answer function instead of an array? | What causes infinite loops in binary search implementations? | N8: 'Binary search the answer' is one of the highest-leverage patterns for mediums/hards. | P8: 0 | Q8: =IF(OR(O8="",P8=0),"",O8+CHOOSE(P8,1,3,7,14,30,90,365))
A9: Not Started | B9: Prefix Sum | C9: 1D/2D prefix sums, difference arrays | D9: Advanced | E9: Arrays | F9: Precompute range sums in O(1) query time after O(n) preprocessing. | G9: 2 | H9: NeetCode - Prefix Sum explained | I9: 'Competitive Programmer's Handbook' Ch.9 (Laaksonen, free PDF) | J9: N/A | K9: LeetCode 560 - Subarray Sum Equals K | L9: Build a range-update range-query tool with a difference array | M9: How does a difference array support O(1) range updates? | Why combine prefix sum with a hashmap for subarray-sum problems? | N9: Difference arrays are the DP-adjacent trick interviewers love to probe. | P9: 0 | Q9: =IF(OR(O9="",P9=0),"",O9+CHOOSE(P9,1,3,7,14,30,90,365))
A10: Not Started | B10: Sliding Window | C10: Fixed & variable window, two pointers | D10: Advanced | E10: Arrays | F10: Reduce O(n^2) brute force scans to O(n) using a shrinking/growing window. | G10: 3 | H10: NeetCode - Sliding Window playlist | I10: 'Elements of Programming Interviews' Ch.5 | J10: N/A | K10: LeetCode 3 - Longest Substring Without Repeating Characters | L10: N/A | M10: How do you decide window growth vs shrink conditions? | When is a fixed-size window preferable to variable? | N10: One of the top-3 highest-frequency FAANG/AI-lab patterns. | P10: 0 | Q10: =IF(OR(O10="",P10=0),"",O10+CHOOSE(P10,1,3,7,14,30,90,365))
A11: Not Started | B11: Monotonic Stack | C11: Next greater/smaller element patterns | D11: Advanced | E11: Stacks | F11: Use a monotonic stack to answer 'next greater element' style queries in O(n). | G11: 3 | H11: NeetCode - Monotonic Stack playlist | I11: 'Elements of Programming Interviews' Ch.8 | J11: N/A | K11: LeetCode 739 - Daily Temperatures | L11: N/A | M11: Why is each element pushed/popped at most once (amortized O(n))? | How does a monotonic stack solve histogram-area problems? | N11: LeetCode 84 (Largest Rectangle in Histogram) is the canonical hard version. | P11: 0 | Q11: =IF(OR(O11="",P11=0),"",O11+CHOOSE(P11,1,3,7,14,30,90,365))
A12: Not Started | B12: Monotonic Queue | C12: Sliding window maximum via deque | D12: Advanced | E12: Monotonic Stack, Sliding Window | F12: Maintain a running window max/min in O(1) amortized using a deque. | G12: 2 | H12: NeetCode - Sliding Window Maximum walkthrough | I12: 'Competitive Programmer's Handbook' Ch.9 | J12: N/A | K12: LeetCode 239 - Sliding Window Maximum | L12: N/A | M12: Why does a deque beat a heap for sliding-window max? | What invariant does the deque maintain? | N12: Common follow-up to the sliding window pattern above. | P12: 0 | Q12: =IF(OR(O12="",P12=0),"",O12+CHOOSE(P12,1,3,7,14,30,90,365))
A13: Trees, Tries & Advanced Structures
A14: Not Started | B14: Trie | C14: Prefix tree construction & search | D14: Advanced | E14: Trees | F14: Build a trie for fast prefix search, autocomplete, and word-break problems. | G14: 3 | H14: NeetCode - Implement Trie | I14: 'Competitive Programmer's Handbook' Ch.10 | J14: N/A | K14: LeetCode 208 - Implement Trie (Prefix Tree) | L14: Build an autocomplete engine backed by a trie | M14: What's the time complexity of trie insert/search vs a hashset? | How do you compress a trie (radix tree)? | N14: Directly relevant to tokenizer vocabulary lookups. | P14: 0 | Q14: =IF(OR(O14="",P14=0),"",O14+CHOOSE(P14,1,3,7,14,30,90,365))
A15: Not Started | B15: Fenwick Tree | C15: Binary Indexed Tree for range sum/update | D15: Expert | E15: Prefix Sum, Bit Manipulation | F15: Support O(log n) point-update and prefix-sum queries. | G15: 4 | H15: Errichto - Fenwick Tree tutorial | I15: 'Competitive Programmer's Handbook' Ch.9.2 | J15: N/A | K15: LeetCode 307 - Range Sum Query - Mutable | L15: Build a live-updating leaderboard using a Fenwick tree | M15: How does the lowbit trick (i & -i) navigate the tree? | When is a Fenwick tree preferable to a segment tree? | N15: Fenwick trees are the 'fast enough, much simpler' alternative to segment trees. | P15: 0 | Q15: =IF(OR(O15="",P15=0),"",O15+CHOOSE(P15,1,3,7,14,30,90,365))
A16: Not Started | B16: Segment Tree | C16: Range queries with lazy propagation | D16: Expert | E16: Fenwick Tree | F16: Build a segment tree supporting range updates and range queries in O(log n). | G16: 5 | H16: Errichto - Segment Tree tutorial | I16: 'Competitive Programmer's Handbook' Ch.9.3 | J16: N/A | K16: LeetCode 218 - The Skyline Problem (segment tree variant) | L16: Build a range-min-query engine with lazy propagation | M16: How does lazy propagation defer updates efficiently? | What's the space complexity of a segment tree? | N16: Segment trees are the go-to when a Fenwick tree can't express the query (e.g. range min). | P16: 0 | Q16: =IF(OR(O16="",P16=0),"",O16+CHOOSE(P16,1,3,7,14,30,90,365))
A17: Not Started | B17: Suffix Array | C17: Suffix sorting & LCP array | D17: Expert | E17: Strings, Sorting | F17: Build a suffix array for fast substring queries on large texts. | G17: 4 | H17: William Fiset - Suffix Array tutorial | I17: 'Algorithms on Strings' (Crochemore) selected chapters | J17: N/A | K17: LeetCode 1044 - Longest Duplicate Substring | L17: N/A | M17: How does the LCP array speed up substring comparisons? | What is the SA-IS construction algorithm's complexity? | N17: Rare in interviews but common in bioinformatics/search-index systems. | P17: 0 | Q17: =IF(OR(O17="",P17=0),"",O17+CHOOSE(P17,1,3,7,14,30,90,365))
A18: Not Started | B18: Suffix Automaton | C18: Minimal DFA for all substrings | D18: Expert | E18: Suffix Array, Automata basics | F18: Understand the suffix automaton as a compact structure for substring existence/counting. | G18: 4 | H18: William Fiset - Suffix Automaton overview | I18: cp-algorithms.com/string/suffix-automaton.html | J18: N/A | K18: Count distinct substrings of a string using a suffix automaton | L18: N/A | M18: Why does a suffix automaton have at most 2n-1 states? | How does it differ from a suffix tree? | N18: Advanced/competitive-programming territory; good for research-engineer breadth. | P18: 0 | Q18: =IF(OR(O18="",P18=0),"",O18+CHOOSE(P18,1,3,7,14,30,90,365))
A19: Not Started | B19: Union Find | C19: Path compression & union by rank | D19: Advanced | E19: Arrays | F19: Implement disjoint set union with near-O(1) amortized operations. | G19: 3 | H19: NeetCode - Union Find explained | I19: 'Elements of Programming Interviews' Ch.9 | J19: N/A | K19: LeetCode 200 - Number of Islands (Union-Find variant) | L19: Build a dynamic connectivity checker for a graph stream | M19: Why does union-by-rank + path compression give near-O(1) amortized time (inverse Ackermann)? | When is Union-Find preferable to BFS/DFS for connectivity? | N19: Kruskal's MST algorithm is built directly on Union-Find. | P19: 0 | Q19: =IF(OR(O19="",P19=0),"",O19+CHOOSE(P19,1,3,7,14,30,90,365))
A20: Graph Theory & Shortest Paths
A21: Not Started | B21: Graph Theory | C21: BFS/DFS traversal, topological sort | D21: Advanced | E21: Trees, Recursion | F21: Master the two foundational graph traversal strategies and their applications. | G21: 3 | H21: NeetCode - Graph Theory playlist | I21: 'Elements of Programming Interviews' Ch.10 | J21: N/A | K21: LeetCode 207 - Course Schedule (topological sort) | L21: N/A | M21: When would you use BFS over DFS for shortest path in unweighted graphs? | How does Kahn's algorithm detect a cycle? | N21: Foundation for almost everything else in this section. | P21: 0 | Q21: =IF(OR(O21="",P21=0),"",O21+CHOOSE(P21,1,3,7,14,30,90,365))
A22: Not Started | B22: Shortest Path | C22: Dijkstra, Bellman-Ford, Floyd-Warshall | D22: Advanced | E22: Graph Theory, Heaps | F22: Compare shortest-path algorithms and know when each applies (negative weights, all-pairs, etc). | G22: 4 | H22: William Fiset - Shortest Path Algorithms playlist | I22: 'Introduction to Algorithms' (CLRS) Ch.24-25 | J22: N/A | K22: LeetCode 743 - Network Delay Time (Dijkstra) | L22: Build a route-finder over a weighted graph with negative edges | M22: Why does Dijkstra fail with negative edge weights? | What's the time complexity of Floyd-Warshall and when is it worth it? | N22: Bellman-Ford's relaxation idea reappears in distributed consensus discussions. | P22: 0 | Q22: =IF(OR(O22="",P22=0),"",O22+CHOOSE(P22,1,3,7,14,30,90,365))
A23: Not Started | B23: Topological Sort | C23: Kahn's algorithm & DFS-based ordering | D23: Advanced | E23: Graph Theory | F23: Order a DAG's nodes such that all edges point forward. | G23: 2 | H23: NeetCode - Topological Sort | I23: 'Elements of Programming Interviews' Ch.10 | J23: N/A | K23: LeetCode 210 - Course Schedule II | L23: N/A | M23: How do you detect a cycle using DFS-based topological sort? | Why does Kahn's algorithm use in-degree counting? | N23: Directly analogous to task/DAG scheduling in Airflow. | P23: 0 | Q23: =IF(OR(O23="",P23=0),"",O23+CHOOSE(P23,1,3,7,14,30,90,365))
A24: Not Started | B24: Maximum Flow | C24: Ford-Fulkerson, Edmonds-Karp, BFS augmenting paths | D24: Expert | E24: Graph Theory, BFS | F24: Compute max flow / min cut on a flow network. | G24: 5 | H24: William Fiset - Max Flow Ford-Fulkerson | I24: 'Introduction to Algorithms' (CLRS) Ch.26 | J24: N/A | K24: LeetCode 1584 (adapted) - build a bipartite matching solver via max flow | L24: N/A | M24: Why does Edmonds-Karp guarantee polynomial time over naive Ford-Fulkerson? | How does max-flow relate to min-cut (max-flow min-cut theorem)? | N24: Rare in interviews but foundational for network/resource-allocation system design. | P24: 0 | Q24: =IF(OR(O24="",P24=0),"",O24+CHOOSE(P24,1,3,7,14,30,90,365))
A25: Not Started | B25: Minimum Cut | C25: Max-flow min-cut theorem applications | D25: Expert | E25: Maximum Flow | F25: Apply the max-flow min-cut duality to partitioning problems. | G25: 3 | H25: William Fiset - Min Cut explained | I25: 'Introduction to Algorithms' (CLRS) Ch.26.2 | J25: N/A | K25: Model a bipartite matching problem as a min-cut problem and solve it | L25: N/A | M25: How would you frame a resource-bottleneck problem as a min-cut problem? | N25: Good for research-engineer-level 'reduce to a known problem' interview questions. | P25: 0 | Q25: =IF(OR(O25="",P25=0),"",O25+CHOOSE(P25,1,3,7,14,30,90,365))
A26: Dynamic Programming, Greedy & Backtracking
A27: Not Started | B27: Dynamic Programming | C27: 1D/2D DP, state design, memoization vs tabulation | D27: Advanced | E27: Recursion | F27: Systematically design DP states and transitions instead of pattern-matching. | G27: 5 | H27: NeetCode - Dynamic Programming playlist | I27: 'Elements of Programming Interviews' Ch.16 | J27: N/A | K27: LeetCode 322 - Coin Change | L27: N/A | M27: How do you identify overlapping subproblems vs optimal substructure? | When does bottom-up beat top-down memoization? | N27: The single highest-leverage topic for FAANG/AI-lab onsites. | P27: 0 | Q27: =IF(OR(O27="",P27=0),"",O27+CHOOSE(P27,1,3,7,14,30,90,365))
A28: Not Started | B28: Advanced DP | C28: Digit DP, bitmask DP, DP on trees | D28: Expert | E28: Dynamic Programming, Bit Manipulation | F28: Extend DP to non-obvious state spaces: digits, subsets, and tree structures. | G28: 5 | H28: Errichto - Advanced DP techniques | I28: 'Competitive Programmer's Handbook' Ch.7 | J28: N/A | K28: LeetCode 1125 - Smallest Sufficient Team (bitmask DP) | L28: N/A | M28: How does DP on trees combine child subtree results at each node? | What's the state space of a bitmask-DP TSP solution? | N28: Research-engineer level; less common but signals real algorithmic depth. | P28: 0 | Q28: =IF(OR(O28="",P28=0),"",O28+CHOOSE(P28,1,3,7,14,30,90,365))
A29: Not Started | B29: Greedy | C29: Exchange argument & interval scheduling | D29: Advanced | E29: Sorting | F29: Prove greedy correctness using exchange arguments rather than intuition alone. | G29: 3 | H29: NeetCode - Greedy playlist | I29: 'Introduction to Algorithms' (CLRS) Ch.16 | J29: N/A | K29: LeetCode 435 - Non-overlapping Intervals | L29: N/A | M29: How do you prove a greedy choice is safe (exchange argument)? | When does greedy fail where DP succeeds? | N29: Interviewers often ask you to justify why greedy works here. | P29: 0 | Q29: =IF(OR(O29="",P29=0),"",O29+CHOOSE(P29,1,3,7,14,30,90,365))
A30: Not Started | B30: Backtracking | C30: Constraint satisfaction & pruning | D30: Advanced | E30: Recursion | F30: Systematically explore solution spaces with pruning for combinatorial problems. | G30: 3 | H30: NeetCode - Backtracking playlist | I30: 'Elements of Programming Interviews' Ch.15 | J30: N/A | K30: LeetCode 51 - N-Queens | L30: N/A | M30: How does backtracking differ from brute-force DFS? | What pruning strategies cut the search space fastest? | N30: N-Queens and Sudoku solvers are the canonical practice set. | P30: 0 | Q30: =IF(OR(O30="",P30=0),"",O30+CHOOSE(P30,1,3,7,14,30,90,365))
A31: Not Started | B31: Computational Geometry | C31: Convex hull, line sweep | D31: Expert | E31: Sorting, Vectors | F31: Apply geometric primitives (cross product, sweep line) to spatial problems. | G31: 3 | H31: William Fiset - Computational Geometry intro | I31: 'Competitive Programmer's Handbook' Ch.29 | J31: N/A | K31: LeetCode 587 - Erect the Fence (convex hull) | L31: N/A | M31: How does the cross product determine turn direction (CCW/CW)? | What's the time complexity of Graham scan? | N31: Rarely asked directly but shows up in spatial-indexing system design. | P31: 0 | Q31: =IF(OR(O31="",P31=0),"",O31+CHOOSE(P31,1,3,7,14,30,90,365))
A32: String Algorithms & Probabilistic Structures
A33: Not Started | B33: String Algorithms | C33: KMP, Z-function, Rabin-Karp | D33: Advanced | E33: Strings | F33: Match patterns in text in linear time instead of naive O(nm). | G33: 4 | H33: NeetCode / Errichto - String Matching Algorithms | I33: 'Competitive Programmer's Handbook' Ch.26 | J33: N/A | K33: LeetCode 28 - Find the Index of the First Occurrence (implement KMP) | L33: N/A | M33: How does the KMP failure function avoid re-scanning characters? | Why is Rabin-Karp's rolling hash O(1) per shift? | N33: KMP's failure function idea reappears in tokenizer/BPE merge logic. | P33: 0 | Q33: =IF(OR(O33="",P33=0),"",O33+CHOOSE(P33,1,3,7,14,30,90,365))
A34: Not Started | B34: Bloom Filter | C34: Probabilistic set membership | D34: Advanced | E34: Hashing basics | F34: Trade a small false-positive rate for O(1) space-efficient membership tests. | G34: 2 | H34: William Fiset - Bloom Filters explained | I34: 'Mining of Massive Datasets' Ch.4 (free Stanford book) | J34: redis.io/docs/data-types/probabilistic/bloom-filter | K34: Implement a Bloom filter from scratch and measure its false-positive rate | L34: Add a Bloom filter in front of a cache to avoid cache-miss storms | M34: How do you choose the number of hash functions to minimize false positives? | Why can't a Bloom filter support deletion? | N34: Directly usable in your Redis-based systems work. | P34: 0 | Q34: =IF(OR(O34="",P34=0),"",O34+CHOOSE(P34,1,3,7,14,30,90,365))
A35: Not Started | B35: HyperLogLog | C35: Cardinality estimation | D35: Expert | E35: Probability basics, Hashing | F35: Estimate distinct-element counts in a stream using sublinear memory. | G35: 3 | H35: Google - HyperLogLog explained (conference talk) | I35: 'Mining of Massive Datasets' Ch.4.4 | J35: redis.io/docs/data-types/probabilistic/hyperloglogs | K35: Implement a simplified HLL and compare its estimate to a true distinct count | L35: N/A | M35: How does HLL use the position of the leftmost 1-bit to estimate cardinality? | What's the typical error rate of HLL? | N35: Redis ships PFADD/PFCOUNT built on this exact structure. | P35: 0 | Q35: =IF(OR(O35="",P35=0),"",O35+CHOOSE(P35,1,3,7,14,30,90,365))
A36: Not Started | B36: Count-Min Sketch | C36: Approximate frequency counting | D36: Advanced | E36: Hashing, Probability | F36: Estimate item frequencies in a stream with bounded error using sublinear space. | G36: 2 | H36: Mining Massive Datasets - Count-Min Sketch lecture (Stanford CS246) | I36: 'Mining of Massive Datasets' Ch.4.5 | J36: N/A | K36: Implement a count-min sketch and measure its overestimation error | L36: N/A | M36: Why does count-min sketch only ever overestimate, never underestimate? | How do width and depth trade off accuracy vs memory? | N36: Useful for rate-limiting and top-k frequency estimation at scale. | P36: 0 | Q36: =IF(OR(O36="",P36=0),"",O36+CHOOSE(P36,1,3,7,14,30,90,365))
A37: Not Started | B37: LRU Cache | C37: Doubly linked list + hashmap design | D37: Advanced | E37: Hashing, Linked Lists | F37: Implement O(1) get/put cache eviction from scratch. | G37: 2 | H37: NeetCode - LRU Cache walkthrough | I37: 'Elements of Programming Interviews' Ch.13 | J37: N/A | K37: LeetCode 146 - LRU Cache | L37: N/A | M37: Why do you need both a hashmap and a doubly linked list? | How would you make an LRU cache thread-safe? | N37: One of the most frequently asked 'design a data structure' interview questions. | P37: 0 | Q37: =IF(OR(O37="",P37=0),"",O37+CHOOSE(P37,1,3,7,14,30,90,365))
A38: Not Started | B38: LFU Cache | C38: Frequency-bucketed eviction design | D38: Expert | E38: LRU Cache | F38: Implement O(1) get/put with least-frequently-used eviction. | G38: 3 | H38: NeetCode - LFU Cache walkthrough | I38: 'Elements of Programming Interviews' Ch.13 (extension) | J38: N/A | K38: LeetCode 460 - LFU Cache | L38: N/A | M38: How do frequency buckets keep LFU operations O(1)? | How do you break ties between equally-frequent items? | N38: A step up in difficulty from LRU; a strong signal question for senior roles. | P38: 0 | Q38: =IF(OR(O38="",P38=0),"",O38+CHOOSE(P38,1,3,7,14,30,90,365))

Sheet Operating Systems
A1: Operating Systems
A2: Kernel, memory, scheduling, and modern I/O interfaces (eBPF, io_uring) relevant to systems-level ML engineering.
A3: Sheet Progress — 25 topics total | Q3: =ROUND(COUNTIF(A5:A33,"Completed")/SUMPRODUCT(COUNTIF(A5:A33,{"Completed","In Progress","Not Started","Research","Project","Optional"}))*100,0) -> 0
A4: Status | B4: Topic | C4: Subtopic | D4: Difficulty | E4: Prerequisites | F4: Learning Goal | G4: Est. Hours | H4: Best YouTube Resource | I4: Best Reading | J4: Official Documentation | K4: Coding Exercise | L4: Mini Project | M4: Interview Questions | N4: Notes | O4: Date Completed | P4: Revision Stage | Q4: Revision Date
A5: Kernel, System Calls & Memory Management
A6: Not Started | B6: Kernel | C6: Monolithic vs microkernel, kernel/user space boundary | D6: Advanced | E6: OS fundamentals | F6: Understand how the kernel mediates all hardware access and enforces isolation. | G6: 3 | H6: Neso Academy - OS Kernel basics | I6: 'Operating Systems: Three Easy Pieces' (OSTEP) Ch.2 (free online) | J6: kernel.org/doc/html/latest/ | K6: Trace a syscall from user space to kernel space with strace | L6: N/A | M6: Why is a syscall slower than a function call? | What's the tradeoff between monolithic and microkernel designs? | N6: OSTEP is the best free resource for this entire sheet. | P6: 0 | Q6: =IF(OR(O6="",P6=0),"",O6+CHOOSE(P6,1,3,7,14,30,90,365))
A7: Not Started | B7: System Calls | C7: syscall mechanism, vDSO, syscall table | D7: Advanced | E7: Kernel | F7: Understand how the syscall instruction transitions privilege levels. | G7: 3 | H7: CS 162 Berkeley - Syscalls lecture | I7: OSTEP Ch.2-3 | J7: man7.org/linux/man-pages/man2/syscalls.2.html | K7: Use strace to profile syscall overhead of a Python script | L7: N/A | M7: What does vDSO optimize (e.g. gettimeofday)? | Why is a context switch required for a syscall? | N7: vDSO avoids a full kernel trap for cheap, frequently-called syscalls. | P7: 0 | Q7: =IF(OR(O7="",P7=0),"",O7+CHOOSE(P7,1,3,7,14,30,90,365))
A8: Not Started | B8: Memory Management | C8: Address spaces, heap/stack layout | D8: Advanced | E8: Kernel | F8: Understand how a process's virtual address space is organized. | G8: 3 | H8: CS 162 Berkeley - Memory Management lecture | I8: OSTEP Ch.13-15 | J8: N/A | K8: Inspect /proc/[pid]/maps for a running process | L8: N/A | M8: Why does every process see its own full address space? | What lives in the heap vs the stack? | N8: Directly useful when debugging container OOM kills. | P8: 0 | Q8: =IF(OR(O8="",P8=0),"",O8+CHOOSE(P8,1,3,7,14,30,90,365))
A9: Not Started | B9: Virtual Memory | C9: Address translation & demand paging | D9: Advanced | E9: Memory Management | F9: Understand how virtual addresses are translated to physical ones on demand. | G9: 4 | H9: CS 162 Berkeley - Virtual Memory lecture | I9: OSTEP Ch.18-19 | J9: N/A | K9: Simulate a simple page table lookup in Python | L9: N/A | M9: What triggers a page fault and how is it handled? | Why is demand paging more efficient than eager loading? | N9: Foundation for understanding container memory limits and OOM behavior. | P9: 0 | Q9: =IF(OR(O9="",P9=0),"",O9+CHOOSE(P9,1,3,7,14,30,90,365))
